<mujoco model="linkerhand_l10_7_right.urdf">
    <compiler angle="radian" />
    <size njmax="500" nconmax="100" />
    <asset>
        <mesh name="hand_base_link" file="hand_base_link.STL" />
        <mesh name="thumb_metacarpals_base1" file="thumb_metacarpals_base1.STL" />
        <mesh name="thumb_metacarpals_base2" file="thumb_metacarpals_base2.STL" />
        <mesh name="thumb_metacarpals" file="thumb_metacarpals.STL" />
        <mesh name="thumb_proximal" file="thumb_proximal.STL" />
        <mesh name="thumb_distal" file="thumb_distal.STL" />
        <mesh name="index_metacarpals" file="index_metacarpals.STL" />
        <mesh name="index_proximal" file="index_proximal.STL" />
        <mesh name="index_middle" file="index_middle.STL" />
        <mesh name="index_distal" file="index_distal.STL" />
        <mesh name="middle_proximal" file="middle_proximal.STL" />
        <mesh name="middle_middle" file="middle_middle.STL" />
        <mesh name="middle_distal" file="middle_distal.STL" />
        <mesh name="ring_metacarpals" file="ring_metacarpals.STL" />
        <mesh name="ring_proximal" file="ring_proximal.STL" />
        <mesh name="ring_middle" file="ring_middle.STL" />
        <mesh name="ring_distal" file="ring_distal.STL" />
        <mesh name="pinky_metacarpals" file="pinky_metacarpals.STL" />
        <mesh name="pinky_proximal" file="pinky_proximal.STL" />
        <mesh name="pinky_middle" file="pinky_middle.STL" />
        <mesh name="pinky_distal" file="pinky_distal.STL" />
    </asset>
    <worldbody>
        <geom type="mesh" rgba="1 0.6 0 1" mesh="hand_base_link" />
        <body name="thumb_metacarpals_base1" pos="-0.013419 0.012551 0.060602">
            <inertial pos="0.0284775 -0.00319296 0.000288698" quat="0.982334 -0.131352 0.00768812 0.133066" mass="0.00845817" diaginertia="1.43534e-06 9.68033e-07 7.1801e-07" />
            <joint name="thumb_cmc_roll" pos="0 0 0" axis="0.999962 0 -0.00872652" limited="true" range="0 1.1339" />
            <geom type="mesh" rgba="0 0 1 1" mesh="thumb_metacarpals_base1" />
            <body name="thumb_metacarpals_base2" pos="0.035797 -0.00065879 0.00045944">
                <inertial pos="0.00215248 0.00687961 -0.00178649" quat="0.987962 -0.0496902 -0.0287532 -0.143649" mass="0.00582711" diaginertia="3.20027e-07 2.71838e-07 1.75578e-07" />
                <joint name="thumb_cmc_yaw" pos="0 0 0" axis="0.00851701 -0.21782 -0.975952" limited="true" range="0 1.9189" />
                <geom type="mesh" rgba="0.898039 0.917647 0.929412 1" mesh="thumb_metacarpals_base2" />
                <body name="thumb_metacarpals" pos="0.0046051 0.014383 -0.0051478" quat="0.491553 -0.408412 -0.343317 -0.688265">
                    <inertial pos="0.00183662 -2.80743e-06 0.0269905" quat="0.706337 -0.033722 -0.0338399 0.706262" mass="0.0152012" diaginertia="3.84771e-06 2.96886e-06 1.30492e-06" />
                    <joint name="thumb_cmc_pitch" pos="0 0 0" axis="0 1 0" limited="true" range="0 0.5146" />
                    <geom type="mesh" rgba="0.592157 0.666667 0.682353 1" mesh="thumb_metacarpals" />
                    <body name="thumb_proximal" pos="0.0061722 0 0.047968">
                        <inertial pos="0.0015927 -4.43358e-06 0.0151574" quat="0.999254 2.82857e-05 -0.038623 -5.34436e-06" mass="0.0066223" diaginertia="1.01869e-06 9.10433e-07 4.44039e-07" />
                        <joint name="thumb_mcp" pos="0 0 0" axis="0 1 0" limited="true" range="0 0.7152" />
                        <geom type="mesh" rgba="0.6 0.6 0.6 1" mesh="thumb_proximal" />
                        <body name="thumb_distal" pos="-0.00017064 0 0.038665">
                            <inertial pos="-0.0013892 1.66654e-06 0.011579" quat="0.955526 0.00103379 -0.294899 -0.00188491" mass="0.00512934" diaginertia="4.02423e-07 3.23808e-07 1.77453e-07" />
                            <joint name="thumb_ip" pos="0 0 0" axis="0 1 0" limited="true" range="0 0.7763" />
                            <geom type="mesh" rgba="0.6 0.4 0.2 1" mesh="thumb_distal" />
                        </body>
                    </body>
                </body>
            </body>
        </body>
        <body name="index_metacarpals" pos="-0.0021643 0.026654 0.13253">
            <inertial pos="-0.000473392 -6.96703e-07 0.00909068" quat="0.582341 0.401173 0.400934 0.582401" mass="0.009037" diaginertia="7.3738e-07 5.63015e-07 4.79402e-07" />
            <joint name="index_mcp_roll" pos="0 0 0" axis="-0.999962 0 0.00872652" limited="true" range="0 0.2181" />
            <geom type="mesh" rgba="0.898039 0.917647 0.929412 1" mesh="index_metacarpals" />
            <body name="index_proximal" pos="0.0020763 0 0.015294">
                <inertial pos="-0.00022141 1.17214e-06 0.0104802" quat="0.705918 -0.0353614 -0.0351217 0.706538" mass="0.00654982" diaginertia="4.58698e-07 4.46166e-07 1.71942e-07" />
                <joint name="index_mcp_pitch" pos="0 0 0" axis="0 1 0" limited="true" range="0 1.3607" />
                <geom type="mesh" rgba="0.647059 0.517647 0 1" mesh="index_proximal" />
                <body name="index_middle" pos="-0.0013807 0 0.035624">
                    <inertial pos="-0.00259933 -2.09526e-06 0.0110175" quat="0.990418 -0.000269623 -0.138103 0.000580602" mass="0.00283044" diaginertia="2.7204e-07 2.33078e-07 1.15541e-07" />
                    <joint name="index_pip" pos="0 0 0" axis="0 1 0" limited="true" range="0 1.8317" />
                    <geom type="mesh" rgba="0 0.6 1 1" mesh="index_middle" />
                    <body name="index_distal" pos="-0.0054686 0 0.025665">
                        <inertial pos="-0.000710605 5.23484e-06 0.0121457" quat="0.973136 -0.00106266 -0.230227 -0.00127848" mass="0.00314459" diaginertia="1.85051e-07 1.48366e-07 7.68285e-08" />
                        <joint name="index_dip" pos="0 0 0" axis="0 1 0" limited="true" range="0 1.8317" />
                        <geom type="mesh" rgba="0 0.6 1 1" mesh="index_distal" />
                    </body>
                </body>
            </body>
        </body>
        <body name="middle_proximal" pos="-0.0021316 0.0076542 0.15281">
            <inertial pos="-0.00022622 1.17216e-06 0.0104801" quat="0.70591 -0.0355235 -0.0352837 0.706529" mass="0.00654982" diaginertia="4.58698e-07 4.46166e-07 1.71942e-07" />
            <joint name="middle_mcp_pitch" pos="0 0 0" axis="0 1 0" limited="true" range="0 1.3607" />
            <geom type="mesh" rgba="0.647059 0.517647 0 1" mesh="middle_proximal" />
            <body name="middle_middle" pos="-0.001397 0 0.035623">
                <inertial pos="-0.00261699 -2.09527e-06 0.0110133" quat="0.990307 -0.00027009 -0.138897 0.000580391" mass="0.00283044" diaginertia="2.7204e-07 2.33078e-07 1.15541e-07" />
                <joint name="middle_pip" pos="0 0 0" axis="0 1 0" limited="true" range="0 1.8317" />
                <geom type="mesh" rgba="0 0.6 1 1" mesh="middle_middle" />
                <body name="middle_distal" pos="-0.0055098 0 0.025656">
                    <inertial pos="-0.000728493 5.23463e-06 0.0121446" quat="0.972966 -0.00106167 -0.230943 -0.00127922" mass="0.00314459" diaginertia="1.85051e-07 1.48366e-07 7.68285e-08" />
                    <joint name="middle_dip" pos="0 0 0" axis="0 1 0" limited="true" range="0 0.628" />
                    <geom type="mesh" rgba="0 0.6 1 1" mesh="middle_distal" />
                </body>
            </body>
        </body>
        <body name="ring_metacarpals" pos="-0.0021643 -0.011346 0.13253">
            <inertial pos="-0.000473392 -6.96703e-07 0.00909068" quat="0.582341 0.401173 0.400934 0.582401" mass="0.009037" diaginertia="7.3738e-07 5.63015e-07 4.79402e-07" />
            <joint name="ring_mcp_roll" pos="0 0 0" axis="0.999962 0 0.00872652" limited="true" range="0 0.2181" />
            <geom type="mesh" rgba="0.898039 0.917647 0.929412 1" mesh="ring_metacarpals" />
            <body name="ring_proximal" pos="0.0020763 0 0.015294">
                <inertial pos="-0.000221412 1.17117e-06 0.0104802" quat="0.705917 -0.0353614 -0.0351215 0.706539" mass="0.00654983" diaginertia="4.58698e-07 4.46166e-07 1.71942e-07" />
                <joint name="ring_mcp_pitch" pos="0 0 0" axis="0 1 0" limited="true" range="0 1.3607" />
                <geom type="mesh" rgba="0.647059 0.517647 0 1" mesh="ring_proximal" />
                <body name="ring_middle" pos="-0.0013807 0 0.035624">
                    <inertial pos="-0.00259933 -2.09537e-06 0.0110175" quat="0.990418 -0.000269632 -0.138103 0.000580637" mass="0.00283044" diaginertia="2.7204e-07 2.33078e-07 1.15541e-07" />
                    <joint name="ring_pip" pos="0 0 0" axis="0 1 0" limited="true" range="0 1.8317" />
                    <geom type="mesh" rgba="0 0.6 1 1" mesh="ring_middle" />
                    <body name="ring_distal" pos="-0.0054686 0 0.025665">
                        <inertial pos="-0.000710605 5.23486e-06 0.0121457" quat="0.973136 -0.00106266 -0.230227 -0.00127848" mass="0.00314459" diaginertia="1.85051e-07 1.48366e-07 7.68285e-08" />
                        <joint name="ring_dip" pos="0 0 0" axis="0 1 0" limited="true" range="0 0.628" />
                        <geom type="mesh" rgba="0 0.6 1 1" mesh="ring_distal" />
                    </body>
                </body>
            </body>
        </body>
        <body name="pinky_metacarpals" pos="-0.00012074 -0.030346 0.12755">
            <inertial pos="-0.000473392 -6.96703e-07 0.00909068" quat="0.582341 0.401173 0.400934 0.582401" mass="0.009037" diaginertia="7.3738e-07 5.63015e-07 4.79402e-07" />
            <joint name="pinky_mcp_roll" pos="0 0 0" axis="0.999962 0 0.00872652" limited="true" range="0 0.3489" />
            <geom type="mesh" rgba="0.898039 0.917647 0.929412 1" mesh="pinky_metacarpals" />
            <body name="pinky_proximal" pos="0.0020763 0 0.015294">
                <inertial pos="-0.000221412 1.17104e-06 0.0104802" quat="0.705917 -0.0353614 -0.0351215 0.706539" mass="0.00654983" diaginertia="4.58698e-07 4.46166e-07 1.71942e-07" />
                <joint name="pinky_mcp_pitch" pos="0 0 0" axis="0 1 0" limited="true" range="0 1.3607" />
                <geom type="mesh" rgba="0 0.6 1 1" mesh="pinky_proximal" />
                <body name="pinky_middle" pos="-0.0013807 0 0.035624">
                    <inertial pos="-0.00259933 -2.09526e-06 0.0110175" quat="0.990418 -0.000269623 -0.138103 0.000580602" mass="0.00283044" diaginertia="2.7204e-07 2.33078e-07 1.15541e-07" />
                    <joint name="pinky_pip" pos="0 0 0" axis="0 1 0" limited="true" range="0 1.8317" />
                    <geom type="mesh" rgba="0 0.6 1 1" mesh="pinky_middle" />
                    <body name="pinky_distal" pos="-0.0054686 0 0.025665">
                        <inertial pos="-0.000710605 5.23471e-06 0.0121457" quat="0.973136 -0.00106262 -0.230227 -0.00127847" mass="0.00314459" diaginertia="1.85051e-07 1.48366e-07 7.68285e-08" />
                        <joint name="pinky_dip" pos="0 0 0" axis="0 1 0" limited="true" range="0 0.628" />
                        <geom type="mesh" rgba="0 0.6 1 1" mesh="pinky_distal" />
                    </body>
                </body>
            </body>
        </body>
    </worldbody>
</mujoco>
